<!-- <?xml version="1.0"?> -->
<sdf version='1.7'>
  <model name='dragonFly'>
<!-- ----- Begin Base and Fixed joints ----- --> 
    
    <link name='base_link'>
	    
      <pose>-0.314716 1.0342 -0.65169 0 -0 0</pose>
      <inertial>
        <pose>0.314716 -1.0342 0.65169 0 -0 0</pose>
	<mass>2</mass>
        <inertia>
		<!--  <ixx>0.182912</ixx> -->
	  <ixx>0.15</ixx>
          <ixy>0</ixy>
          <ixz>0</ixz>
          <iyy>0.25</iyy>
          <iyz>0</iyz>
          <izz>0.15</izz>
        </inertia>
      </inertial>
    
    <!-- OLD VERSION OF BASE LINK 
    <link name='base_link'>
      <inertial>
        <pose>0.300198 -1.03708 0.641994 0 -0 0</pose>
        <mass>2.16435</mass>
        <inertia>
          <ixx>0.194727</ixx>
          <ixy>0.00891674</ixy>
          <ixz>0.00705715</ixz>
          <iyy>0.0884838</iyy>
          <iyz>-0.00495212</iyz>
          <izz>0.250912</izz>
        </inertia>
      </inertial>
     -->
      
      
      <collision name='base_link_collision'>
        <pose>0 0 0 0 -0 0</pose>
        <geometry>
          <mesh>
            <scale>1 1 1</scale>
            <uri>model://dragonFly/meshes/base_link.STL</uri>
          </mesh>
        </geometry>
      </collision>
      
      <collision name='base_link_fixed_joint_lump__Link_Bvert_collision_1'>
        <pose>0.31542 -0.62495 0.6111 -3.14159 -0 1.5708</pose>
        <geometry>
          <mesh>
            <scale>1 1 1</scale>
            <uri>model://dragonFly/meshes/Link_Bvert.STL</uri>
          </mesh>
        </geometry>
      </collision>
      
      <collision name='base_link_fixed_joint_lump__Link_Lhorz_collision_2'>
        <pose>0.35292 -0.62495 0.6486 1.5708 -0 1.5708</pose>
        <geometry>
          <mesh>
            <scale>1 1 1</scale>
            <uri>model://dragonFly/meshes/Link_Lhorz.STL</uri>
          </mesh>
        </geometry>
      </collision>
      
      <collision name='base_link_fixed_joint_lump__Link_Rhorz_collision_4'>
        <pose>0.27792 -0.62495 0.6486 -1.5708 0 1.5708</pose>
        <geometry>
          <mesh>
            <scale>1 1 1</scale>
            <uri>model://dragonFly/meshes/Link_Rhorz.STL</uri>
          </mesh>
        </geometry>
      </collision>
     
      
      <collision name='base_link_fixed_joint_lump__Link_Tvert_collision_6'>
        <pose>0.31542 -0.62495 0.6861 -3.14159 -0 1.5708</pose>
        <geometry>
          <mesh>
            <scale>1 1 1</scale>
            <uri>model://dragonFly/meshes/Link_Tvert.STL</uri>
          </mesh>
        </geometry>
      </collision>
      
      <collision name='base_link_fixed_joint_lump__Rail_collision_7'>
        <pose>0.436528 -1.39999 0.526984 1.5708 -0.785398 0</pose>
        <geometry>
          <mesh>
            <scale>1 1 1</scale>
            <uri>model://dragonFly/meshes/Rail.STL</uri>
          </mesh>
        </geometry>
      </collision>
      
      <visual name='base_link_visual'>
        <pose>0 0 0 0 -0 0</pose>
        <geometry>
          <mesh>
            <scale>1 1 1</scale>
            <uri>model://dragonFly/meshes/base_link.STL</uri>
          </mesh>
        </geometry>
      </visual>
      
      <visual name='base_link_fixed_joint_lump__Link_Bvert_visual_1'>
        <pose>0.31542 -0.62495 0.6111 -3.14159 -0 1.5708</pose>
        <geometry>
          <mesh>
            <scale>1 1 1</scale>
            <uri>model://dragonFly/meshes/Link_Bvert.STL</uri>
          </mesh>
        </geometry>
      </visual>
      
      <visual name='base_link_fixed_joint_lump__Link_Lhorz_visual_2'>
        <pose>0.35292 -0.62495 0.6486 1.5708 -0 1.5708</pose>
        <geometry>
          <mesh>
            <scale>1 1 1</scale>
            <uri>model://dragonFly/meshes/Link_Lhorz.STL</uri>
          </mesh>
        </geometry>
      </visual>
      
      
      
      <!-- OLD VERSION OF LEFT WING
      <collision name='base_link_fixed_joint_lump__Link_Lwing_collision_3'>
        <pose>0.41042 -0.86495 0.72922 1.5708 -0 1.581</pose>
        <geometry>
          <mesh>
            <scale>1 1 1</scale>
            <uri>model://dragonFly/meshes/Link_Lwing.STL</uri>
          </mesh>
        </geometry>
      </collision>
      
      <visual name='base_link_fixed_joint_lump__Link_Lwing_visual_3'>
        <pose>0.41042 -0.86495 0.72922 1.5708 -0 1.581</pose>
        <geometry>
          <mesh>
            <scale>1 1 1</scale>
            <uri>model://dragonFly/meshes/Link_Lwing.STL</uri>
          </mesh>
        </geometry>
      </visual>
      -->
      
    
      <visual name='base_link_fixed_joint_lump__Link_Rhorz_visual_4'>
        <pose>0.27792 -0.62495 0.6486 -1.5708 0 1.5708</pose>
        <geometry>
          <mesh>
            <scale>1 1 1</scale>
            <uri>model://dragonFly/meshes/Link_Rhorz.STL</uri>
          </mesh>
        </geometry>
      </visual>
      
      
      <!-- OLD VERSION OF RIGHT WING JOINT
      <collision name='base_link_fixed_joint_lump__Link_Rwing_collision_5'>
        <pose>0.22042 -0.86495 0.68422 1.5708 0 1.5785</pose>
        <geometry>
          <mesh>
            <scale>1 1 1</scale>
            <uri>model://dragonFly/meshes/Link_Rwing.STL</uri>
          </mesh>
        </geometry>
      </collision>
      
      <visual name='base_link_fixed_joint_lump__Link_Rwing_visual_5'>
        <pose>0.22042 -0.86495 0.68422 1.5708 0 1.5785</pose>
        <geometry>
          <mesh>
            <scale>1 1 1</scale>
            <uri>model://dragonFly/meshes/Link_Rwing.STL</uri>
          </mesh>
        </geometry>
      </visual>
      
      -->
      
    
      
      <visual name='base_link_fixed_joint_lump__Link_Tvert_visual_6'>
        <pose>0.31542 -0.62495 0.6861 -3.14159 -0 1.5708</pose>
        <geometry>
          <mesh>
            <scale>1 1 1</scale>
            <uri>model://dragonFly/meshes/Link_Tvert.STL</uri>
          </mesh>
        </geometry>
      </visual>
      
      <visual name='base_link_fixed_joint_lump__Rail_visual_7'>
        <pose>0.436528 -1.39999 0.526984 1.5708 -0.785398 0</pose>
        <geometry>
          <mesh>
            <scale>1 1 1</scale>
            <uri>model://dragonFly/meshes/Rail.STL</uri>
          </mesh>
        </geometry>
      </visual>
    </link>
    
    <!-- ----- End of Base and Fixed joints ----- -->
    
    <!-- ----- Begin Left and Right Wing Fixed Joints ----- -->
    
    <joint name='Joint_Lwing' type='fixed'>
      <pose relative_to='base_link'>0.41042 -0.86495 0.72922 1.5708 -0 1.581</pose>
      <parent>base_link</parent>
      <child>Link_Lwing</child>
      <axis>
        <xyz>0 1 0</xyz>
        <limit>
          <lower>0</lower>
          <upper>0</upper>
          <effort>0</effort>
          <velocity>0</velocity>
        </limit>
        <dynamics>
          <spring_reference>0</spring_reference>
          <spring_stiffness>0</spring_stiffness>
        </dynamics>
      </axis>
    </joint>
    
    <link name='Link_Lwing'>
      <pose relative_to='Joint_Lwing'>0 0 0 0 -0 0</pose>
      <inertial>
        <pose>-0.128829 0.011503 0.235065 0 -0 0</pose>
        <!--<mass>0.097064</mass>-->
        <mass>0.310904</mass>
        <inertia>
          <ixx>0.00277333</ixx>
          <ixy>-6.04797e-07</ixy>
          <ixz>0.00032246</ixz>
          <iyy>0.00304285</iyy>
          <iyz>2.54356e-06</iyz>
          <izz>0.000276725</izz>
        </inertia>
      </inertial>
      
      <collision name='Link_Lwing_collision'>
        <pose>0 0 0 0 -0 0</pose>
        <geometry>
          <mesh>
            <scale>1 1 1</scale>
            <uri>model://dragonFly/meshes/Link_Lwing.STL</uri>
          </mesh>
        </geometry>
      </collision>
      <visual name='Link_Lwing_visual'>
        <pose>0 0 0 0 -0 0</pose>
        <geometry>
          <mesh>
            <scale>1 1 1</scale>
            <uri>model://dragonFly/meshes/Link_Lwing.STL</uri>
          </mesh>
        </geometry>
 	<material>
          <script>
            <name>Gazebo/Blue</name>
            <uri>__default__</uri>
          </script>
        </material>
        <plugin name="left_elevon_lift_visual" filename="libForceVisual.so">
          <topic_name>lift_force/left_elevon</topic_name>
          <color>Gazebo/Red</color>
        </plugin>
      </visual>
    </link>
    
    
    
    <joint name='Joint_Rwing' type='fixed'>
      <pose relative_to='base_link'>0.22042 -0.86495 0.68422 1.5708 0 1.5785</pose>
      <parent>base_link</parent>
      <child>Link_Rwing</child>
      <axis>
        <xyz>0 1 0</xyz>
        <limit>
          <lower>0</lower>
          <upper>0</upper>
          <effort>0</effort>
          <velocity>0</velocity>
        </limit>
        <dynamics>
          <spring_reference>0</spring_reference>
          <spring_stiffness>0</spring_stiffness>
        </dynamics>
      </axis>
    </joint>
    
    <link name='Link_Rwing'>
      <pose relative_to='Joint_Rwing'>0 0 0 0 -0 0</pose>
      <inertial>
        <pose>-0.103579 0.011507 -0.247219 0 -0 0</pose>
        <mass>0.310904</mass>
        <inertia>
          <ixx>0.00901141</ixx>
          <ixy>-1.00882e-06</ixy>
          <ixz>-0.000180332</ixz>
          <iyy>0.00974705</iyy>
          <iyz>-8.08271e-06</iyz>
          <izz>0.000758858</izz>
        </inertia>
      </inertial>
      
      <collision name='Link_Rwing_collision'>
        <pose>0 0 0 0 -0 0</pose>
        <geometry>
          <mesh>
            <scale>1 1 1</scale>
            <uri>model://dragonFly/meshes/Link_Rwing.STL</uri>
          </mesh>
        </geometry>
      </collision>
      
      <visual name='Link_Rwing_visual'>
        <pose>0 0 0 0 -0 0</pose>
        <geometry>
          <mesh>
            <scale>1 1 1</scale>
            <uri>model://dragonFly/meshes/Link_Rwing.STL</uri>
          </mesh>
        </geometry>
        <material>
          <script>
            <name>Gazebo/Blue</name>
            <uri>__default__</uri>
          </script>
        </material>
        <plugin name="right_elevon_lift_visual" filename="libForceVisual.so">
          <topic_name>lift_force/right_elevon</topic_name>
          <color>Gazebo/Green</color>
        </plugin>
      </visual>
    </link>
    
    
    <!-- ----- End of Left and Right Wing Fixed Joints ----- -->
    
    
    
    <!-- ----- Begin Rotor ----- -->
    
    <joint name='rotor_puller_joint' type='revolute'>
      <pose relative_to='base_link'>0.300198 -1.63708 0.641994 0 1.57 -1.57</pose>
      <child>rotor_puller</child>
      <parent>base_link</parent>
      <axis>
        <xyz>0 0 1</xyz>
        <limit>
          <lower>-1e+16</lower>
          <upper>1e+16</upper>
        </limit>
        <dynamics>
          <spring_reference>0</spring_reference>
          <spring_stiffness>0</spring_stiffness>
        </dynamics>
        <use_parent_model_frame>1</use_parent_model_frame>
      </axis>
    </joint>
    <link name='rotor_puller'>
      <pose relative_to='rotor_puller_joint'>0 0 0.1 0 0 0</pose>
      <inertial>
        <pose>0 0 -0.1 0 0 0</pose>
	<!--<mass>0.005</mass>-->
        <mass>0.00001</mass>
        <inertia>
          <ixx>9.75e-07</ixx>
          <ixy>0</ixy>
          <ixz>0</ixz>
          <iyy>0.000166704</iyy>
          <iyz>0</iyz>
          <izz>0.000167604</izz>
        </inertia>
      </inertial>
      <collision name='rotor_puller_collision'>
	      <pose>0.0 0 0.0 0 0 0</pose>
        <geometry>
          <cylinder>
            <length>0.005</length>
            <radius>0.1</radius>
          </cylinder>
        </geometry>
        <surface>
          <contact>
            <ode/>
          </contact>
          <friction>
            <ode/>
          </friction>
        </surface>
      </collision>
      <visual name='rotor_puller_visual'>
        <pose>0 0 -0.09 0 0 0</pose>
        <geometry>
          <mesh>
            <scale>1 1 1</scale>
            <uri>model://dragonFly/meshes/iris_prop_ccw.dae</uri>
          </mesh>
        </geometry>
        <material>
          <script>
            <name>Gazebo/Blue</name>
            <uri>__default__</uri>
          </script>
        </material>
      </visual>
      <gravity>1</gravity>
      <velocity_decay/>
      <self_collide>0</self_collide>
    </link>
    
    <!-- ----- End of Rotor ----- -->
    
    
    
    
    <!-- ----- Begin revolute joints ----- -->
    
    <joint name='Joint_Link_Bvert_Lflap' type='revolute'>
      <pose relative_to='base_link'>0.315419 -0.56295 0.5161 -3.14159 -0 1.57084</pose>
      <parent>base_link</parent>
      <child>Link_Bvert_Lflap</child>
      <axis>
        <xyz>0 0 1</xyz>
        <limit>
          <lower>-0.53</lower>
          <upper>0.53</upper>
          <effort>10</effort>
          <velocity>0</velocity>
        </limit>
        <dynamics>
          <spring_reference>0</spring_reference>
          <spring_stiffness>0</spring_stiffness>
        </dynamics>
      </axis>
    </joint>
    <link name='Link_Bvert_Lflap'>
      <pose relative_to='Joint_Link_Bvert_Lflap'>0 0 0 0 -0 0</pose>
      <inertial>
        <pose>0.047161 0.004129 0.078468 0 -0 0</pose>
        <mass>0.0263709</mass>
        <inertia>
          <ixx>4.9583e-05</ixx>
          <ixy>-2.92453e-07</ixy>
          <ixz>4.22893e-06</ixz>
          <iyy>8.25345e-05</iyy>
          <iyz>3.12255e-07</iyz>
          <izz>3.38828e-05</izz>
        </inertia>
      </inertial>
      <collision name='Link_Bvert_Lflap_collision'>
        <pose>0 0 0 0 -0 0</pose>
        <geometry>
          <mesh>
            <scale>1 1 1</scale>
            <uri>model://dragonFly/meshes/Link_Bvert_Lflap.STL</uri>
          </mesh>
        </geometry>
      </collision>
      <visual name='Link_Bvert_Lflap_visual'>
        <pose>0 0 0 0 -0 0</pose>
        <geometry>
          <mesh>
            <scale>1 1 1</scale>
            <uri>model://dragonFly/meshes/Link_Bvert_Lflap.STL</uri>
          </mesh>
        </geometry>
        <material>
          <script>
            <name>Gazebo/Blue</name>
            <uri>__default__</uri>
          </script>
        </material>
      </visual>
    </link>
    
    <!-- REMOVE RIGHT FLAP (FOR SIMPLICITY)
    <joint name='Joint_Link_Bvert_Rflap' type='revolute'>
      <pose relative_to='base_link'>0.325419 -0.56295 0.5161 7e-06 -0 1.57094</pose>
      <parent>base_link</parent>
      <child>Link_Bvert_Rflap</child>
      <axis>
        <xyz>0 0 1</xyz>
        <limit>
          <lower>0</lower>
          <upper>1.5707</upper>
          <effort>10</effort>
          <velocity>0</velocity>
        </limit>
        <dynamics>
          <spring_reference>0</spring_reference>
          <spring_stiffness>0</spring_stiffness>
        </dynamics>
      </axis>
    </joint>
    <link name='Link_Bvert_Rflap'>
      <pose relative_to='Joint_Link_Bvert_Rflap'>0 0 0 0 -0 0</pose>
      <inertial>
        <pose>0.047168 0.014062 -0.071532 0 -0 0</pose>
        <mass>0.0263709</mass>
        <inertia>
          <ixx>4.95822e-05</ixx>
          <ixy>-2.45675e-07</ixy>
          <ixz>4.22937e-06</ixz>
          <iyy>8.25353e-05</iyy>
          <iyz>3.06243e-07</iyz>
          <izz>3.38828e-05</izz>
        </inertia>
      </inertial>
      <collision name='Link_Bvert_Rflap_collision'>
        <pose>0 0 0 0 -0 0</pose>
        <geometry>
          <mesh>
            <scale>1 1 1</scale>
            <uri>model://dragonFly/meshes/Link_Bvert_Rflap.STL</uri>
          </mesh>
        </geometry>
      </collision>
      <visual name='Link_Bvert_Rflap_visual'>
        <pose>0 0 0 0 -0 0</pose>
        <geometry>
          <mesh>
            <scale>1 1 1</scale>
            <uri>model://dragonFly/meshes/Link_Bvert_Rflap.STL</uri>
          </mesh>
        </geometry>
      </visual>
    </link>
    REMOVE RIGHT FLAP (FOR SIMPLICITY) -->
    
    <!-- REMOVE BOTTOM FLAP (FOR SIMPLICITY)
    <joint name='Joint_Link_Lhorz_Bflap' type='revolute'>
      <pose relative_to='base_link'>0.44792 -0.562938 0.6586 -1.57079 0.014984 1.5708</pose>
      <parent>base_link</parent>
      <child>Link_Lhorz_Bflap</child>
      <axis>
        <xyz>0 0 1</xyz>
        <limit>
          <lower>-1.5707</lower>
          <upper>0</upper>
          <effort>10</effort>
          <velocity>0</velocity>
        </limit>
        <dynamics>
          <spring_reference>0</spring_reference>
          <spring_stiffness>0</spring_stiffness>
        </dynamics>
      </axis>
    </joint>
    
    <link name='Link_Lhorz_Bflap'>
      <pose relative_to='Joint_Link_Lhorz_Bflap'>0 0 0 0 -0 0</pose>
      <inertial>
        <pose>0.047382 0.013048 -0.071532 0 -0 0</pose>
        <mass>0.0263709</mass>
        <inertia>
          <ixx>4.95866e-05</ixx>
          <ixy>4.61785e-07</ixy>
          <ixz>4.23492e-06</ixz>
          <iyy>8.25295e-05</iyy>
          <iyz>2.15333e-07</iyz>
          <izz>3.38819e-05</izz>
        </inertia>
      </inertial>
      <collision name='Link_Lhorz_Bflap_collision'>
        <pose>0 0 0 0 -0 0</pose>
        <geometry>
          <mesh>
            <scale>1 1 1</scale>
            <uri>model://dragonFly/meshes/Link_Lhorz_Bflap.STL</uri>
          </mesh>
        </geometry>
      </collision>
      <visual name='Link_Lhorz_Bflap_visual'>
        <pose>0 0 0 0 -0 0</pose>
        <geometry>
          <mesh>
            <scale>1 1 1</scale>
            <uri>model://dragonFly/meshes/Link_Lhorz_Bflap.STL</uri>
          </mesh>
        </geometry>
      </visual>
    </link>
    REMOVE BOTTOM FLAP (FOR SIMPLICITY) -->
    

    
    <joint name='Joint_Link_Lhorz_Tflap' type='revolute'>
      <pose relative_to='base_link'>0.44792 -0.56295 0.6486 1.5708 0.001177 1.5708</pose>
      <parent>base_link</parent>
      <child>Link_Lhorz_Tflap</child>
      <axis>
        <xyz>0 0 1</xyz>
        <limit>
          <lower>-0.53</lower>
          <upper>0.53</upper>
          <effort>10</effort>
          <velocity>0</velocity>
        </limit>
        <dynamics>
          <spring_reference>0</spring_reference>
          <spring_stiffness>0</spring_stiffness>
        </dynamics>
      </axis>
    </joint>
    <link name='Link_Lhorz_Tflap'>
      <pose relative_to='Joint_Link_Lhorz_Tflap'>0 0 0 0 -0 0</pose>
      <inertial>
        <pose>0.047184 0.003862 0.078468 0 -0 0</pose>
        <mass>0.0263709</mass>
        <inertia>
          <ixx>4.95805e-05</ixx>
          <ixy>-1.0565e-07</ixy>
          <ixz>4.23059e-06</ixz>
          <iyy>8.25356e-05</iyy>
          <iyz>2.8823e-07</iyz>
          <izz>3.38819e-05</izz>
        </inertia>
      </inertial>
      <collision name='Link_Lhorz_Tflap_collision'>
        <pose>0 0 0 0 -0 0</pose>
        <geometry>
          <mesh>
            <scale>1 1 1</scale>
            <uri>model://dragonFly/meshes/Link_Lhorz_Tflap.STL</uri>
          </mesh>
        </geometry>
      </collision>
      <visual name='Link_Lhorz_Tflap_visual'>
        <pose>0 0 0 0 -0 0</pose>
        <geometry>
          <mesh>
            <scale>1 1 1</scale>
            <uri>model://dragonFly/meshes/Link_Lhorz_Tflap.STL</uri>
          </mesh>
        </geometry>
        <material>
          <script>
            <name>Gazebo/Blue</name>
            <uri>__default__</uri>
          </script>
        </material>
      </visual>
    </link>
    
     <!-- REMOVE BOTTOM FLAP (FOR SIMPLICITY)
    <joint name='Joint_Link_Rhorz_Bflap' type='revolute'>
      <pose relative_to='base_link'>0.18292 -0.563012 0.658599 -1.5708 -0.002098 1.5708</pose>
      <parent>base_link</parent>
      <child>Link_Rhorz_Bflap</child>
      <axis>
        <xyz>0 0 1</xyz>
        <limit>
          <lower>-1.5707</lower>
          <upper>0</upper>
          <effort>10</effort>
          <velocity>0</velocity>
        </limit>
        <dynamics>
          <spring_reference>0</spring_reference>
          <spring_stiffness>0</spring_stiffness>
        </dynamics>
      </axis>
    </joint>
    
    <link name='Link_Rhorz_Bflap'>
      <pose relative_to='Joint_Link_Rhorz_Bflap'>0 0 0 0 -0 0</pose>
      <inertial>
        <pose>0.047205 0.014101 0.078468 0 -0 0</pose>
        <mass>0.0263709</mass>
        <inertia>
          <ixx>4.95826e-05</ixx>
          <ixy>-2.72738e-07</ixy>
          <ixz>4.22912e-06</ixz>
          <iyy>8.25348e-05</iyy>
          <iyz>3.09707e-07</iyz>
          <izz>3.38828e-05</izz>
        </inertia>
      </inertial>
      <collision name='Link_Rhorz_Bflap_collision'>
        <pose>0 0 0 0 -0 0</pose>
        <geometry>
          <mesh>
            <scale>1 1 1</scale>
            <uri>model://dragonFly/meshes/Link_Rhorz_Bflap.STL</uri>
          </mesh>
        </geometry>
      </collision>
      <visual name='Link_Rhorz_Bflap_visual'>
        <pose>0 0 0 0 -0 0</pose>
        <geometry>
          <mesh>
            <scale>1 1 1</scale>
            <uri>model://dragonFly/meshes/Link_Rhorz_Bflap.STL</uri>
          </mesh>
        </geometry>
      </visual>
    </link>
    REMOVE BOTTOM FLAP (FOR SIMPLICITY) -->
    
    <joint name='Joint_Link_Rhorz_Tflap' type='revolute'>
      <pose relative_to='base_link'>0.18292 -0.56295 0.6486 1.57079 -0.00617 1.5708</pose>
      <parent>base_link</parent>
      <child>Link_Rhorz_Tflap</child>
      <axis>
        <xyz>0 0 1</xyz>
        <limit>
          <lower>-0.53</lower>
          <upper>0.53</upper>
          <effort>10</effort>
          <velocity>0</velocity>
        </limit>
        <dynamics>
          <spring_reference>0</spring_reference>
          <spring_stiffness>0</spring_stiffness>
        </dynamics>
      </axis>
    </joint>

    <link name='Link_Rhorz_Tflap'>
      <pose relative_to='Joint_Link_Rhorz_Tflap'>0 0 0 0 -0 0</pose>
      <inertial>
        <pose>0.047225 0.003327 -0.071532 0 -0 0</pose>
        <mass>0.0263709</mass>
        <inertia>
          <ixx>4.95824e-05</ixx>
          <ixy>2.6807e-07</ixy>
          <ixz>4.23358e-06</ixz>
          <iyy>8.25338e-05</iyy>
          <iyz>2.40209e-07</iyz>
          <izz>3.38819e-05</izz>
        </inertia>
      </inertial>
      <collision name='Link_Rhorz_Tflap_collision'>
        <pose>0 0 0 0 -0 0</pose>
        <geometry>
          <mesh>
            <scale>1 1 1</scale>
            <uri>model://dragonFly/meshes/Link_Rhorz_Tflap.STL</uri>
          </mesh>
        </geometry>
      </collision>
      <visual name='Link_Rhorz_Tflap_visual'>
        <pose>0 0 0 0 -0 0</pose>
        <geometry>
          <mesh>
            <scale>1 1 1</scale>
            <uri>model://dragonFly/meshes/Link_Rhorz_Tflap.STL</uri>
          </mesh>
        </geometry>
        <material>
          <script>
            <name>Gazebo/Blue</name>
            <uri>__default__</uri>
          </script>
        </material>
      </visual>
    </link>

    <joint name='Joint_Link_Tvert_Lflap' type='revolute'>
      <pose relative_to='base_link'>0.31542 -0.56295 0.7811 -3.14159 -0 1.57777</pose>
      <parent>base_link</parent>
      <child>Link_Tvert_Lflap</child>
      <axis>
        <xyz>0 0 1</xyz>
        <limit>
          <lower>-0.53</lower>
          <upper>0.53</upper>
          <effort>10</effort>
          <velocity>0</velocity>
        </limit>
        <dynamics>
          <spring_reference>0</spring_reference>
          <spring_stiffness>0</spring_stiffness>
        </dynamics>
      </axis>
    </joint>
    <link name='Link_Tvert_Lflap'>
      <pose relative_to='Joint_Link_Tvert_Lflap'>0 0 0 0 -0 0</pose>
      <inertial>
        <pose>0.047134 0.00443 -0.071532 0 -0 0</pose>
        <mass>0.0263709</mass>
        <inertia>
          <ixx>4.9588e-05</ixx>
          <ixy>-5.02259e-07</ixy>
          <ixz>4.22686e-06</ixz>
          <iyy>8.25295e-05</iyy>
          <iyz>3.39174e-07</iyz>
          <izz>3.38828e-05</izz>
        </inertia>
      </inertial>
      <collision name='Link_Tvert_Lflap_collision'>
        <pose>0 0 0 0 -0 0</pose>
        <geometry>
          <mesh>
            <scale>1 1 1</scale>
            <uri>model://dragonFly/meshes/Link_Tvert_Lflap.STL</uri>
          </mesh>
        </geometry>
      </collision>
      <visual name='Link_Tvert_Lflap_visual'>
        <pose>0 0 0 0 -0 0</pose>
        <geometry>
          <mesh>
            <scale>1 1 1</scale>
            <uri>model://dragonFly/meshes/Link_Tvert_Lflap.STL</uri>
          </mesh>
        </geometry>
        <material>
          <script>
            <name>Gazebo/Blue</name>
            <uri>__default__</uri>
          </script>
        </material>
      </visual>
    </link>


    <!-- REMOVE RIGHT FLAP (FOR SIMPLICITY)
    <joint name='Joint_Link_Tvert_Rflap' type='revolute'>
      <pose relative_to='base_link'>0.32542 -0.56288 0.7811 1.5e-05 0 1.57069</pose>
      <parent>base_link</parent>
      <child>Link_Tvert_Rflap</child>
      <axis>
        <xyz>0 0 1</xyz>
        <limit>
          <lower>0</lower>
          <upper>1.5707</upper>
          <effort>10</effort>
          <velocity>0</velocity>
        </limit>
        <dynamics>
          <spring_reference>0</spring_reference>
          <spring_stiffness>0</spring_stiffness>
        </dynamics>
      </axis>
    </joint>
    <link name='Link_Tvert_Rflap'>
      <pose relative_to='Joint_Link_Tvert_Rflap'>0 0 0 0 -0 0</pose>
      <inertial>
        <pose>0.047135 0.01358 0.078468 0 -0 0</pose>
        <mass>0.0263709</mass>
        <inertia>
          <ixx>4.95804e-05</ixx>
          <ixy>9.0676e-08</ixy>
          <ixz>4.23223e-06</ixz>
          <iyy>8.25357e-05</iyy>
          <iyz>2.6299e-07</iyz>
          <izz>3.38819e-05</izz>
        </inertia>
      </inertial>
      <collision name='Link_Tvert_Rflap_collision'>
        <pose>0 0 0 0 -0 0</pose>
        <geometry>
          <mesh>
            <scale>1 1 1</scale>
            <uri>model://dragonFly/meshes/Link_Tvert_Rflap.STL</uri>
          </mesh>
        </geometry>
      </collision>
      <visual name='Link_Tvert_Rflap_visual'>
        <pose>0 0 0 0 -0 0</pose>
        <geometry>
          <mesh>
            <scale>1 1 1</scale>
            <uri>model://dragonFly/meshes/Link_Tvert_Rflap.STL</uri>
          </mesh>
        </geometry>
      </visual>
    </link>
    REMOVE RIGHT FLAP (FOR SIMPLICITY) -->
    
    <!-- ----- End of revolute joints ----- -->

    <!-- ---- Begin IMU plugins ----- -->

    <!--
    <link name='dragonFly/imu_link'>
      <pose relative_to='dragonFly/imu_joint'>0 0 0 0 0 0</pose>
      <inertial>
        <pose>0 0 0 0 0 0</pose>
        <mass>0.015</mass>
        <inertia>
          <ixx>1e-05</ixx>
          <ixy>0</ixy>
          <ixz>0</ixz>
          <iyy>1e-05</iyy>
          <iyz>0</iyz>
          <izz>1e-05</izz>
        </inertia>
      </inertial>
      <self_collide>0</self_collide>
    </link>
    <joint name='dragonFly/imu_joint' type='revolute'>
      <child>dragonFly/imu_link</child>
      <parent>base_link</parent>
      <axis>
        <xyz>0 0 1</xyz>
        <limit>
          <lower>0</lower>
          <upper>0</upper>
          <effort>0</effort>
          <velocity>0</velocity>
        </limit>
        <dynamics>
          <spring_reference>0</spring_reference>
          <spring_stiffness>0</spring_stiffness>
        </dynamics>
        <use_parent_model_frame>1</use_parent_model_frame>
      </axis>
    </joint>
    
    <include>
      <uri>model://airspeed</uri>
      <pose relative_to='airspeed_joint'>0 0 0 0 0 0</pose>
      <name>airspeed</name>
    </include>

    <joint name='airspeed_joint' type='fixed'>
      <child>airspeed::link</child>
      <parent>base_link</parent>
    </joint>
    <include>
      <uri>model://gps</uri>
      <pose relative_to='gps_joint'>0 0 0 0 0 0</pose>
      <name>gps</name>
    </include>
    <joint name='gps_joint' type='fixed'>
      <child>gps::link</child>
      <parent>base_link</parent>
    </joint>
    <include>
      <uri>model://magnetometer</uri>
      <pose relative_to='mag_joint'>0 0 0 0 0 0</pose>
      <name>mag</name>
    </include>
    <joint name='mag_joint' type='fixed'>
      <child>mag::link</child>
      <parent>base_link</parent>
	    </joint>
    -->

    <include>
      <uri>model://imu</uri>
      <pose relative_to='imu_joint'>0 0 0 0 0 0</pose>
      <name>imu</name>
    </include>
    <joint name='imu_joint' type='revolute'>
      <child>imu::link</child>
      <parent>base_link</parent>
      <axis>
        <xyz>1 0 0</xyz>
        <limit>
          <lower>0</lower>
          <upper>0</upper>
          <effort>0</effort>
          <velocity>0</velocity>
        </limit>
        <dynamics>
          <spring_reference>0</spring_reference>
          <spring_stiffness>0</spring_stiffness>
        </dynamics>
        <use_parent_model_frame>1</use_parent_model_frame>
      </axis>
    </joint>
    
    <include>
      <uri>model://airspeed</uri>
      <pose relative_to='airspeed_joint'>0 0 0 0 0 0</pose>
      <name>airspeed</name>
    </include>
    
    <joint name='airspeed_joint' type='fixed'>
      <child>airspeed::link</child>
      <parent>base_link</parent>
    </joint>
    
    
    
    <include>
      <uri>model://gps</uri>
      <pose relative_to='gps_joint'>0 0 0 0 0 0</pose>
      <name>gps</name>
    </include>
    <joint name='gps_joint' type='fixed'>
      <child>gps::link</child>
      <parent>base_link</parent>
    </joint>
    
    <include>
      <uri>model://magnetometer</uri>
      <pose relative_to='mag_joint'>0 0 0 0 0 0</pose>
      <name>mag</name>
    </include>
    <joint name='mag_joint' type='fixed'>
      <child>mag::link</child>
      <parent>base_link</parent>
    </joint>

    <!-- ----- End of IMU ----- -->



    <!-- Begin PX4 plugins -->
    <plugin name="left_wing" filename="libLiftDragPlugin.so">
      <a0>0.05984281113</a0>
      <cla>4.752798721</cla>
      <cda>0.6417112299</cda>
      <cma>0</cma>
      <alpha_stall>0.3391428111</alpha_stall>
      <cla_stall>-3.85</cla_stall>
      <cda_stall>-0.9233984055</cda_stall>
      <cma_stall>0</cma_stall>
     <cp>0.41042 -0.86495 0.72922</cp>
      <cp>0.095704 0.16925 0.07753</cp>
      <area>1.8</area>
      <air_density>1.2041</air_density>
      <forward>0 -1 0</forward>
      <upward>0 0 1</upward>
      <link_name>base_link</link_name>
      <topic_name>lift_force/left_elevon</topic_name>
      <control_joint_name>
        Joint_Lwing
      </control_joint_name>
      <control_joint_rad_to_cl>-0.3</control_joint_rad_to_cl>
      <robotNamespace></robotNamespace>
      <windSubTopic>world_wind</windSubTopic>
    </plugin>

    <plugin name="right_wing" filename="libLiftDragPlugin.so">
      <a0>0.05984281113</a0>
      <cla>4.752798721</cla>
      <cda>0.6417112299</cda>
      <cma>0</cma>
      <alpha_stall>0.3391428111</alpha_stall>
      <cla_stall>-3.85</cla_stall>
      <cda_stall>-0.9233984055</cda_stall>
      <cma_stall>0</cma_stall>
     <cp>0.22042 -0.86495 0.68422</cp>
      <cp>-0.094296 0.16925  0.03253</cp>
      <area>1.8</area>
      <air_density>1.2041</air_density>
      <forward>0 -1 0</forward>
      <upward>0 0 1</upward>
      <link_name>base_link</link_name>
      <topic_name>lift_force/right_elevon</topic_name>
      <control_joint_name>
        Joint_Rwing
      </control_joint_name>
      <control_joint_rad_to_cl>-0.3</control_joint_rad_to_cl>
      <robotNamespace></robotNamespace>
      <windSubTopic>world_wind</windSubTopic>
    </plugin>
    <plugin name="left_flap" filename="libLiftDragPlugin.so">
      <a0>-0.2</a0>
      <cla>4.752798721</cla>
      <cda>0.6417112299</cda>
      <cma>0.0</cma>
      <alpha_stall>0.3391428111</alpha_stall>
      <cla_stall>-3.85</cla_stall>
      <cda_stall>-0.9233984055</cda_stall>
      <cma_stall>0</cma_stall>	    
      <cp>0.44792 -0.56295 0.6486</cp>
      <area>0.06</area>
      <air_density>1.2041</air_density>
      <forward>0 -1 0</forward>
      <upward>0 0 1</upward>
      <link_name>base_link</link_name>
      <control_joint_name>
	Joint_Link_Lhorz_Tflap
      </control_joint_name>
      <control_joint_rad_to_cl>-0.1</control_joint_rad_to_cl>
      <robotNamespace></robotNamespace>
      <windSubTopic>world_wind</windSubTopic>
    </plugin>


    <plugin name="right_flap" filename="libLiftDragPlugin.so">
      <a0>-0.2</a0>
      <cla>4.752798721</cla>
      <cda>0.6417112299</cda>
      <cma>0.0</cma>
      <alpha_stall>0.3391428111</alpha_stall>
      <cla_stall>-3.85</cla_stall>
      <cda_stall>-0.9233984055</cda_stall>
      <cma_stall>0</cma_stall>	    
      <cp>0.18292 -0.56295 0.6486</cp>
      <area>0.06</area>
      <air_density>1.2041</air_density>
      <forward>0 -1 0</forward>
      <upward>0 0 1</upward>
      <link_name>base_link</link_name>
      <control_joint_name>
	Joint_Link_Rhorz_Tflap
      </control_joint_name>
      <control_joint_rad_to_cl>-0.1</control_joint_rad_to_cl>
      <robotNamespace></robotNamespace>
      <windSubTopic>world_wind</windSubTopic>
    </plugin>
    <plugin name="top_rudder" filename="libLiftDragPlugin.so">
      <a0>0.0</a0>
      <cla>4.752798721</cla>
      <cda>0.6417112299</cda>
      <cma>0.0</cma>
      <alpha_stall>0.3391428111</alpha_stall>
      <cla_stall>-3.85</cla_stall>
      <cda_stall>-0.9233984055</cda_stall>
      <cma_stall>0</cma_stall>	    
      <cp>0.31542 -0.56295 0.7811</cp>
      <area>0.06</area>
      <air_density>1.2041</air_density>
      <forward>0 -1 0</forward>
      <upward>0 1 0</upward>
      <link_name>base_link</link_name>
      <control_joint_name>
        Joint_Link_Tvert_Lflap
      </control_joint_name>
      <control_joint_rad_to_cl>0.8</control_joint_rad_to_cl>
      <robotNamespace></robotNamespace>
      <windSubTopic>world_wind</windSubTopic>
    </plugin>

    <plugin name="bottom_rudder" filename="libLiftDragPlugin.so">
       <a0>0.0</a0>
      <cla>4.752798721</cla>
      <cda>0.6417112299</cda>
      <cma>0.0</cma>
      <alpha_stall>0.3391428111</alpha_stall>
      <cla_stall>-3.85</cla_stall>
      <cda_stall>-0.9233984055</cda_stall>
      <cma_stall>0</cma_stall>
      <cp>0.315419 -0.56295 0.5161</cp>
      <area>0.06</area>
      <air_density>1.2041</air_density>
      <forward>0 -1 0</forward>
      <upward>0 1 0</upward>
      <link_name>base_link</link_name>
      <control_joint_name>
        Joint_Link_Bvert_Lflap
      </control_joint_name>
      <control_joint_rad_to_cl>0.8</control_joint_rad_to_cl>
      <robotNamespace></robotNamespace>
      <windSubTopic>world_wind</windSubTopic>
    </plugin>
    <plugin name='puller' filename='libgazebo_motor_model.so'>
      <robotNamespace></robotNamespace>
      <jointName>rotor_puller_joint</jointName>
      <linkName>rotor_puller</linkName>
      <turningDirection>cw</turningDirection>
      <timeConstantUp>0.0125</timeConstantUp>
      <timeConstantDown>0.025</timeConstantDown>
      <maxRotVelocity>3500</maxRotVelocity>
      <motorConstant>8.54858e-06</motorConstant>
      <momentConstant>0.01</momentConstant>
      <commandSubTopic>/gazebo/command/motor_speed</commandSubTopic>
      <motorNumber>4</motorNumber>
      <rotorDragCoefficient>8.06428e-05</rotorDragCoefficient>
      <rollingMomentCoefficient>1e-06</rollingMomentCoefficient>
      <motorSpeedPubTopic>/motor_speed/4</motorSpeedPubTopic>
      <rotorVelocitySlowdownSim>10</rotorVelocitySlowdownSim>
      <robotNamespace></robotNamespace>
      <windSubTopic>world_wind</windSubTopic>
    </plugin>

    <plugin name='groundtruth_plugin' filename='libgazebo_groundtruth_plugin.so'>
      <robotNamespace/>
    </plugin>

    <plugin name='barometer_plugin' filename='libgazebo_barometer_plugin.so'>
      <robotNamespace/>
      <pubRate>50</pubRate>
      <baroTopic>/baro</baroTopic>
    </plugin>
    <plugin name='mavlink_interface' filename='libgazebo_mavlink_interface.so'>
      <robotNamespace></robotNamespace>
      <imuSubTopic>/imu</imuSubTopic>
      <magSubTopic>/mag</magSubTopic>
      <baroSubTopic>/baro</baroSubTopic>
      <mavlink_addr>INADDR_ANY</mavlink_addr>
      <mavlink_tcp_port>{{ mavlink_tcp_port }}</mavlink_tcp_port>
      <mavlink_udp_port>{{ mavlink_udp_port }}</mavlink_udp_port>
      <serialEnabled>{{ serial_enabled }}</serialEnabled>
      <serialDevice>{{ serial_device }}</serialDevice>
      <baudRate>{{ serial_baudrate }}</baudRate>
      <qgc_addr>INADDR_ANY</qgc_addr>
      <qgc_udp_port>14550</qgc_udp_port>
      <sdk_addr>INADDR_ANY</sdk_addr>
      <sdk_udp_port>14540</sdk_udp_port>
      <hil_mode>false</hil_mode>
      <hil_state_level>false</hil_state_level>
      <enable_lockstep>true</enable_lockstep>
      <use_tcp>true</use_tcp>
      <motorSpeedCommandPubTopic>/gazebo/command/motor_speed</motorSpeedCommandPubTopic>
      <control_channels>
        <channel name="top_rudder">
          <input_index>2</input_index>
          <input_offset>0</input_offset>
          <input_scaling>1</input_scaling>
          <zero_position_disarmed>0</zero_position_disarmed>
          <zero_position_armed>0</zero_position_armed>
          <joint_control_type>position_kinematic</joint_control_type>
          <joint_name>Joint_Link_Tvert_Lflap</joint_name>
        </channel>
        <channel name="bottom_rudder">
          <input_index>3</input_index>
          <input_offset>0</input_offset>
          <input_scaling>1</input_scaling>
          <zero_position_disarmed>0</zero_position_disarmed>
          <zero_position_armed>0</zero_position_armed>
          <joint_control_type>position_kinematic</joint_control_type>
          <joint_name>Joint_Link_Bvert_Lflap</joint_name>
        </channel>
        <channel name="rotor4">
          <input_index>4</input_index>
          <input_offset>0</input_offset>
	  <!-- <input_scaling>3500</input_scaling> -->
          <input_scaling>5000</input_scaling>
          <zero_position_disarmed>0</zero_position_disarmed>
          <zero_position_armed>0</zero_position_armed>
          <joint_control_type>velocity</joint_control_type>
          <joint_name>rotor_puller_joint</joint_name>
        </channel>
          <channel name="left_flap">
          <input_index>7</input_index>
          <input_offset>0</input_offset>
          <input_scaling>-1</input_scaling>
          <zero_position_disarmed>0</zero_position_disarmed>
          <zero_position_armed>0</zero_position_armed>
          <joint_control_type>position_kinematic</joint_control_type>
          <joint_name>Joint_Link_Lhorz_Tflap</joint_name>
        </channel>
        <channel name="right_flap">
          <input_index>8</input_index>
          <input_offset>0</input_offset>
          <input_scaling>-1</input_scaling>
          <zero_position_disarmed>0</zero_position_disarmed>
          <zero_position_armed>0</zero_position_armed>
          <joint_control_type>position_kinematic</joint_control_type>
          <joint_name>Joint_Link_Rhorz_Tflap</joint_name>
  	</channel>
        <channel name="left_elevon">
          <input_index>5</input_index>
          <input_offset>0</input_offset>
          <input_scaling>1</input_scaling>
          <zero_position_disarmed>0</zero_position_disarmed>
          <zero_position_armed>0</zero_position_armed>
          <joint_control_type>position_kinematic</joint_control_type>
          <joint_name>Joint_Lwing</joint_name>
        </channel>
        <channel name="right_elevon">
          <input_index>6</input_index>
          <input_offset>0</input_offset>
          <input_scaling>1</input_scaling>
          <zero_position_disarmed>0</zero_position_disarmed>
          <zero_position_armed>0</zero_position_armed>
          <joint_control_type>position_kinematic</joint_control_type>
          <joint_name>Joint_Rwing</joint_name>
        </channel>
      </control_channels>
    </plugin>
    
    <static>0</static>
    
  </model>
</sdf>
